Traceback (most recent call last):
  File "/opt/conda/envs/pysumma/lib/python3.7/site-packages/jupyter_cache/executors/utils.py", line 56, in single_nb_execution
    record_timing=False,
  File "/opt/conda/envs/pysumma/lib/python3.7/site-packages/nbclient/client.py", line 1087, in execute
    return NotebookClient(nb=nb, resources=resources, km=km, **kwargs).execute()
  File "/opt/conda/envs/pysumma/lib/python3.7/site-packages/nbclient/util.py", line 74, in wrapped
    return just_run(coro(*args, **kwargs))
  File "/opt/conda/envs/pysumma/lib/python3.7/site-packages/nbclient/util.py", line 53, in just_run
    return loop.run_until_complete(coro)
  File "/opt/conda/envs/pysumma/lib/python3.7/asyncio/base_events.py", line 587, in run_until_complete
    return future.result()
  File "/opt/conda/envs/pysumma/lib/python3.7/site-packages/nbclient/client.py", line 541, in async_execute
    cell, index, execution_count=self.code_cells_executed + 1
  File "/opt/conda/envs/pysumma/lib/python3.7/site-packages/nbclient/client.py", line 832, in async_execute_cell
    self._check_raise_for_error(cell, exec_reply)
  File "/opt/conda/envs/pysumma/lib/python3.7/site-packages/nbclient/client.py", line 740, in _check_raise_for_error
    raise CellExecutionError.from_cell_and_msg(cell, exec_reply['content'])
nbclient.exceptions.CellExecutionError: An error occurred while executing the following cell:
------------------
summa_exe = "/usr/bin/summa.exe"
file_manager = './data/yakima/file_manager.txt'
shapefile = './data/yakima/shapefile/yakima.shp'
gdf = gpd.GeoDataFrame.from_file(shapefile)
------------------

[0;31m---------------------------------------------------------------------------[0m
[0;31mCPLE_OpenFailedError[0m                      Traceback (most recent call last)
[0;32mfiona/_shim.pyx[0m in [0;36mfiona._shim.gdal_open_vector[0;34m()[0m

[0;32mfiona/_err.pyx[0m in [0;36mfiona._err.exc_wrap_pointer[0;34m()[0m

[0;31mCPLE_OpenFailedError[0m: ./data/yakima/shapefile/yakima.shp: No such file or directory

During handling of the above exception, another exception occurred:

[0;31mDriverError[0m                               Traceback (most recent call last)
[0;32m<ipython-input-2-c14997a03de4>[0m in [0;36m<module>[0;34m[0m
[1;32m      2[0m [0mfile_manager[0m [0;34m=[0m [0;34m'./data/yakima/file_manager.txt'[0m[0;34m[0m[0;34m[0m[0m
[1;32m      3[0m [0mshapefile[0m [0;34m=[0m [0;34m'./data/yakima/shapefile/yakima.shp'[0m[0;34m[0m[0;34m[0m[0m
[0;32m----> 4[0;31m [0mgdf[0m [0;34m=[0m [0mgpd[0m[0;34m.[0m[0mGeoDataFrame[0m[0;34m.[0m[0mfrom_file[0m[0;34m([0m[0mshapefile[0m[0;34m)[0m[0;34m[0m[0;34m[0m[0m
[0m
[0;32m/opt/conda/envs/pysumma/lib/python3.7/site-packages/geopandas/geodataframe.py[0m in [0;36mfrom_file[0;34m(cls, filename, **kwargs)[0m
[1;32m    374[0m         [0;34m>>[0m[0;34m>[0m [0mdf[0m [0;34m=[0m [0mgeopandas[0m[0;34m.[0m[0mGeoDataFrame[0m[0;34m.[0m[0mfrom_file[0m[0;34m([0m[0;34m'nybb.shp'[0m[0;34m)[0m[0;34m[0m[0;34m[0m[0m
[1;32m    375[0m         """
[0;32m--> 376[0;31m         [0;32mreturn[0m [0mgeopandas[0m[0;34m.[0m[0mio[0m[0;34m.[0m[0mfile[0m[0;34m.[0m[0m_read_file[0m[0;34m([0m[0mfilename[0m[0;34m,[0m [0;34m**[0m[0mkwargs[0m[0;34m)[0m[0;34m[0m[0;34m[0m[0m
[0m[1;32m    377[0m [0;34m[0m[0m
[1;32m    378[0m     [0;34m@[0m[0mclassmethod[0m[0;34m[0m[0;34m[0m[0m

[0;32m/opt/conda/envs/pysumma/lib/python3.7/site-packages/geopandas/io/file.py[0m in [0;36m_read_file[0;34m(filename, bbox, mask, rows, **kwargs)[0m
[1;32m     94[0m [0;34m[0m[0m
[1;32m     95[0m     [0;32mwith[0m [0mfiona_env[0m[0;34m([0m[0;34m)[0m[0;34m:[0m[0;34m[0m[0;34m[0m[0m
[0;32m---> 96[0;31m         [0;32mwith[0m [0mreader[0m[0;34m([0m[0mpath_or_bytes[0m[0;34m,[0m [0;34m**[0m[0mkwargs[0m[0;34m)[0m [0;32mas[0m [0mfeatures[0m[0;34m:[0m[0;34m[0m[0;34m[0m[0m
[0m[1;32m     97[0m [0;34m[0m[0m
[1;32m     98[0m             [0;31m# In a future Fiona release the crs attribute of features will[0m[0;34m[0m[0;34m[0m[0;34m[0m[0m

[0;32m/opt/conda/envs/pysumma/lib/python3.7/site-packages/fiona/env.py[0m in [0;36mwrapper[0;34m(*args, **kwargs)[0m
[1;32m    398[0m     [0;32mdef[0m [0mwrapper[0m[0;34m([0m[0;34m*[0m[0margs[0m[0;34m,[0m [0;34m**[0m[0mkwargs[0m[0;34m)[0m[0;34m:[0m[0;34m[0m[0;34m[0m[0m
[1;32m    399[0m         [0;32mif[0m [0mlocal[0m[0;34m.[0m[0m_env[0m[0;34m:[0m[0;34m[0m[0;34m[0m[0m
[0;32m--> 400[0;31m             [0;32mreturn[0m [0mf[0m[0;34m([0m[0;34m*[0m[0margs[0m[0;34m,[0m [0;34m**[0m[0mkwargs[0m[0;34m)[0m[0;34m[0m[0;34m[0m[0m
[0m[1;32m    401[0m         [0;32melse[0m[0;34m:[0m[0;34m[0m[0;34m[0m[0m
[1;32m    402[0m             [0;32mif[0m [0misinstance[0m[0;34m([0m[0margs[0m[0;34m[[0m[0;36m0[0m[0;34m][0m[0;34m,[0m [0mstr[0m[0;34m)[0m[0;34m:[0m[0;34m[0m[0;34m[0m[0m

[0;32m/opt/conda/envs/pysumma/lib/python3.7/site-packages/fiona/__init__.py[0m in [0;36mopen[0;34m(fp, mode, driver, schema, crs, encoding, layer, vfs, enabled_drivers, crs_wkt, **kwargs)[0m
[1;32m    255[0m         [0;32mif[0m [0mmode[0m [0;32min[0m [0;34m([0m[0;34m'a'[0m[0;34m,[0m [0;34m'r'[0m[0;34m)[0m[0;34m:[0m[0;34m[0m[0;34m[0m[0m
[1;32m    256[0m             c = Collection(path, mode, driver=driver, encoding=encoding,
[0;32m--> 257[0;31m                            layer=layer, enabled_drivers=enabled_drivers, **kwargs)
[0m[1;32m    258[0m         [0;32melif[0m [0mmode[0m [0;34m==[0m [0;34m'w'[0m[0;34m:[0m[0;34m[0m[0;34m[0m[0m
[1;32m    259[0m             [0;32mif[0m [0mschema[0m[0;34m:[0m[0;34m[0m[0;34m[0m[0m

[0;32m/opt/conda/envs/pysumma/lib/python3.7/site-packages/fiona/collection.py[0m in [0;36m__init__[0;34m(self, path, mode, driver, schema, crs, encoding, layer, vsi, archive, enabled_drivers, crs_wkt, ignore_fields, ignore_geometry, **kwargs)[0m
[1;32m    160[0m             [0;32mif[0m [0mself[0m[0;34m.[0m[0mmode[0m [0;34m==[0m [0;34m'r'[0m[0;34m:[0m[0;34m[0m[0;34m[0m[0m
[1;32m    161[0m                 [0mself[0m[0;34m.[0m[0msession[0m [0;34m=[0m [0mSession[0m[0;34m([0m[0;34m)[0m[0;34m[0m[0;34m[0m[0m
[0;32m--> 162[0;31m                 [0mself[0m[0;34m.[0m[0msession[0m[0;34m.[0m[0mstart[0m[0;34m([0m[0mself[0m[0;34m,[0m [0;34m**[0m[0mkwargs[0m[0;34m)[0m[0;34m[0m[0;34m[0m[0m
[0m[1;32m    163[0m             [0;32melif[0m [0mself[0m[0;34m.[0m[0mmode[0m [0;32min[0m [0;34m([0m[0;34m'a'[0m[0;34m,[0m [0;34m'w'[0m[0;34m)[0m[0;34m:[0m[0;34m[0m[0;34m[0m[0m
[1;32m    164[0m                 [0mself[0m[0;34m.[0m[0msession[0m [0;34m=[0m [0mWritingSession[0m[0;34m([0m[0;34m)[0m[0;34m[0m[0;34m[0m[0m

[0;32mfiona/ogrext.pyx[0m in [0;36mfiona.ogrext.Session.start[0;34m()[0m

[0;32mfiona/_shim.pyx[0m in [0;36mfiona._shim.gdal_open_vector[0;34m()[0m

[0;31mDriverError[0m: ./data/yakima/shapefile/yakima.shp: No such file or directory
DriverError: ./data/yakima/shapefile/yakima.shp: No such file or directory

